2022-02-05 08:00:24,715 - django.request - log_response - ERROR - Internal Server Error: /api/enrichment
Traceback (most recent call last):
  File "/Users/uzair/Dev/GreedyBear/env/lib/python3.9/site-packages/django/core/handlers/exception.py", line 47, in inner
    response = get_response(request)
  File "/Users/uzair/Dev/GreedyBear/env/lib/python3.9/site-packages/django/core/handlers/base.py", line 181, in _get_response
    response = wrapped_callback(request, *callback_args, **callback_kwargs)
  File "/Users/uzair/Dev/GreedyBear/env/lib/python3.9/site-packages/django/views/decorators/csrf.py", line 54, in wrapped_view
    return view_func(*args, **kwargs)
  File "/Users/uzair/Dev/GreedyBear/env/lib/python3.9/site-packages/django/views/generic/base.py", line 70, in view
    return self.dispatch(request, *args, **kwargs)
  File "/Users/uzair/Dev/GreedyBear/env/lib/python3.9/site-packages/rest_framework/views.py", line 509, in dispatch
    response = self.handle_exception(exc)
  File "/Users/uzair/Dev/GreedyBear/env/lib/python3.9/site-packages/rest_framework/views.py", line 469, in handle_exception
    self.raise_uncaught_exception(exc)
  File "/Users/uzair/Dev/GreedyBear/env/lib/python3.9/site-packages/rest_framework/views.py", line 480, in raise_uncaught_exception
    raise exc
  File "/Users/uzair/Dev/GreedyBear/env/lib/python3.9/site-packages/rest_framework/views.py", line 506, in dispatch
    response = handler(request, *args, **kwargs)
  File "/Users/uzair/Dev/GreedyBear/env/lib/python3.9/site-packages/rest_framework/decorators.py", line 50, in handler
    return func(*args, **kwargs)
  File "/Users/uzair/Dev/GreedyBear/api/views.py", line 152, in enrichment_view
    serializer.is_valid(raise_exception=True)
  File "/Users/uzair/Dev/GreedyBear/env/lib/python3.9/site-packages/rest_framework/serializers.py", line 227, in is_valid
    self._validated_data = self.run_validation(self.initial_data)
  File "/Users/uzair/Dev/GreedyBear/env/lib/python3.9/site-packages/rest_framework/serializers.py", line 429, in run_validation
    value = self.validate(value)
  File "/Users/uzair/Dev/GreedyBear/api/serializers.py", line 37, in validate
    if not re.match(REGEX_IP, observable) or not re.match(REGEX_DOMAIN, observable):
  File "/Library/Frameworks/Python.framework/Versions/3.9/lib/python3.9/re.py", line 191, in match
    return _compile(pattern, flags).match(string)
TypeError: expected string or bytes-like object
2022-02-05 08:00:24,717 - django.server - log_message - ERROR - "GET /api/enrichment?query=140.246.171.141 HTTP/1.1" 500 116390
2022-02-05 08:01:56,088 - django.request - log_response - ERROR - Internal Server Error: /api/enrichment
Traceback (most recent call last):
  File "/Users/uzair/Dev/GreedyBear/env/lib/python3.9/site-packages/django/core/handlers/exception.py", line 47, in inner
    response = get_response(request)
  File "/Users/uzair/Dev/GreedyBear/env/lib/python3.9/site-packages/django/core/handlers/base.py", line 181, in _get_response
    response = wrapped_callback(request, *callback_args, **callback_kwargs)
  File "/Users/uzair/Dev/GreedyBear/env/lib/python3.9/site-packages/django/views/decorators/csrf.py", line 54, in wrapped_view
    return view_func(*args, **kwargs)
  File "/Users/uzair/Dev/GreedyBear/env/lib/python3.9/site-packages/django/views/generic/base.py", line 70, in view
    return self.dispatch(request, *args, **kwargs)
  File "/Users/uzair/Dev/GreedyBear/env/lib/python3.9/site-packages/rest_framework/views.py", line 509, in dispatch
    response = self.handle_exception(exc)
  File "/Users/uzair/Dev/GreedyBear/env/lib/python3.9/site-packages/rest_framework/views.py", line 469, in handle_exception
    self.raise_uncaught_exception(exc)
  File "/Users/uzair/Dev/GreedyBear/env/lib/python3.9/site-packages/rest_framework/views.py", line 480, in raise_uncaught_exception
    raise exc
  File "/Users/uzair/Dev/GreedyBear/env/lib/python3.9/site-packages/rest_framework/views.py", line 506, in dispatch
    response = handler(request, *args, **kwargs)
  File "/Users/uzair/Dev/GreedyBear/env/lib/python3.9/site-packages/rest_framework/decorators.py", line 50, in handler
    return func(*args, **kwargs)
  File "/Users/uzair/Dev/GreedyBear/api/views.py", line 152, in enrichment_view
    serializer.is_valid(raise_exception=True)
  File "/Users/uzair/Dev/GreedyBear/env/lib/python3.9/site-packages/rest_framework/serializers.py", line 227, in is_valid
    self._validated_data = self.run_validation(self.initial_data)
  File "/Users/uzair/Dev/GreedyBear/env/lib/python3.9/site-packages/rest_framework/serializers.py", line 429, in run_validation
    value = self.validate(value)
  File "/Users/uzair/Dev/GreedyBear/api/serializers.py", line 36, in validate
    if not re.match(REGEX_IP, observable) or not re.match(REGEX_DOMAIN, observable):
  File "/Library/Frameworks/Python.framework/Versions/3.9/lib/python3.9/re.py", line 191, in match
    return _compile(pattern, flags).match(string)
TypeError: expected string or bytes-like object
2022-02-05 08:01:56,090 - django.server - log_message - ERROR - "GET /api/enrichment?query=140.246.171.141 HTTP/1.1" 500 116137
2022-02-05 08:04:08,624 - django.request - log_response - ERROR - Internal Server Error: /api/enrichment
Traceback (most recent call last):
  File "/Users/uzair/Dev/GreedyBear/env/lib/python3.9/site-packages/django/core/handlers/exception.py", line 47, in inner
    response = get_response(request)
  File "/Users/uzair/Dev/GreedyBear/env/lib/python3.9/site-packages/django/core/handlers/base.py", line 181, in _get_response
    response = wrapped_callback(request, *callback_args, **callback_kwargs)
  File "/Users/uzair/Dev/GreedyBear/env/lib/python3.9/site-packages/django/views/decorators/csrf.py", line 54, in wrapped_view
    return view_func(*args, **kwargs)
  File "/Users/uzair/Dev/GreedyBear/env/lib/python3.9/site-packages/django/views/generic/base.py", line 70, in view
    return self.dispatch(request, *args, **kwargs)
  File "/Users/uzair/Dev/GreedyBear/env/lib/python3.9/site-packages/rest_framework/views.py", line 509, in dispatch
    response = self.handle_exception(exc)
  File "/Users/uzair/Dev/GreedyBear/env/lib/python3.9/site-packages/rest_framework/views.py", line 469, in handle_exception
    self.raise_uncaught_exception(exc)
  File "/Users/uzair/Dev/GreedyBear/env/lib/python3.9/site-packages/rest_framework/views.py", line 480, in raise_uncaught_exception
    raise exc
  File "/Users/uzair/Dev/GreedyBear/env/lib/python3.9/site-packages/rest_framework/views.py", line 506, in dispatch
    response = handler(request, *args, **kwargs)
  File "/Users/uzair/Dev/GreedyBear/env/lib/python3.9/site-packages/rest_framework/decorators.py", line 50, in handler
    return func(*args, **kwargs)
  File "/Users/uzair/Dev/GreedyBear/api/views.py", line 152, in enrichment_view
    serializer.is_valid(raise_exception=True)
  File "/Users/uzair/Dev/GreedyBear/env/lib/python3.9/site-packages/rest_framework/serializers.py", line 227, in is_valid
    self._validated_data = self.run_validation(self.initial_data)
  File "/Users/uzair/Dev/GreedyBear/env/lib/python3.9/site-packages/rest_framework/serializers.py", line 429, in run_validation
    value = self.validate(value)
  File "/Users/uzair/Dev/GreedyBear/api/serializers.py", line 36, in validate
    if not re.match(REGEX_IP, observable) or not re.match(REGEX_DOMAIN, observable):
  File "/Library/Frameworks/Python.framework/Versions/3.9/lib/python3.9/re.py", line 191, in match
    return _compile(pattern, flags).match(string)
TypeError: expected string or bytes-like object
2022-02-05 08:04:08,626 - django.server - log_message - ERROR - "GET /api/enrichment?query=140.246.171.141 HTTP/1.1" 500 115962
2022-02-05 08:08:29,803 - django.request - log_response - ERROR - Internal Server Error: /api/enrichment
Traceback (most recent call last):
  File "/Users/uzair/Dev/GreedyBear/env/lib/python3.9/site-packages/django/core/handlers/exception.py", line 47, in inner
    response = get_response(request)
  File "/Users/uzair/Dev/GreedyBear/env/lib/python3.9/site-packages/django/core/handlers/base.py", line 181, in _get_response
    response = wrapped_callback(request, *callback_args, **callback_kwargs)
  File "/Users/uzair/Dev/GreedyBear/env/lib/python3.9/site-packages/django/views/decorators/csrf.py", line 54, in wrapped_view
    return view_func(*args, **kwargs)
  File "/Users/uzair/Dev/GreedyBear/env/lib/python3.9/site-packages/django/views/generic/base.py", line 70, in view
    return self.dispatch(request, *args, **kwargs)
  File "/Users/uzair/Dev/GreedyBear/env/lib/python3.9/site-packages/rest_framework/views.py", line 509, in dispatch
    response = self.handle_exception(exc)
  File "/Users/uzair/Dev/GreedyBear/env/lib/python3.9/site-packages/rest_framework/views.py", line 469, in handle_exception
    self.raise_uncaught_exception(exc)
  File "/Users/uzair/Dev/GreedyBear/env/lib/python3.9/site-packages/rest_framework/views.py", line 480, in raise_uncaught_exception
    raise exc
  File "/Users/uzair/Dev/GreedyBear/env/lib/python3.9/site-packages/rest_framework/views.py", line 506, in dispatch
    response = handler(request, *args, **kwargs)
  File "/Users/uzair/Dev/GreedyBear/env/lib/python3.9/site-packages/rest_framework/decorators.py", line 50, in handler
    return func(*args, **kwargs)
  File "/Users/uzair/Dev/GreedyBear/api/views.py", line 152, in enrichment_view
    serializer.is_valid(raise_exception=True)
  File "/Users/uzair/Dev/GreedyBear/env/lib/python3.9/site-packages/rest_framework/serializers.py", line 227, in is_valid
    self._validated_data = self.run_validation(self.initial_data)
  File "/Users/uzair/Dev/GreedyBear/env/lib/python3.9/site-packages/rest_framework/serializers.py", line 429, in run_validation
    value = self.validate(value)
  File "/Users/uzair/Dev/GreedyBear/api/serializers.py", line 37, in validate
    if not re.match(REGEX_IP, observable) or not re.match(REGEX_DOMAIN, observable):
  File "/Library/Frameworks/Python.framework/Versions/3.9/lib/python3.9/re.py", line 191, in match
    return _compile(pattern, flags).match(string)
TypeError: expected string or bytes-like object
2022-02-05 08:08:29,806 - django.server - log_message - ERROR - "GET /api/enrichment?query=140.246.171.141 HTTP/1.1" 500 116431
2022-02-05 08:08:48,957 - django.request - log_response - ERROR - Internal Server Error: /api/enrichment
Traceback (most recent call last):
  File "/Users/uzair/Dev/GreedyBear/env/lib/python3.9/site-packages/rest_framework/fields.py", line 457, in get_attribute
    return get_attribute(instance, self.source_attrs)
  File "/Users/uzair/Dev/GreedyBear/env/lib/python3.9/site-packages/rest_framework/fields.py", line 97, in get_attribute
    instance = getattr(instance, attr)
AttributeError: 'IOC' object has no attribute 'query'

During handling of the above exception, another exception occurred:

Traceback (most recent call last):
  File "/Users/uzair/Dev/GreedyBear/env/lib/python3.9/site-packages/django/core/handlers/exception.py", line 47, in inner
    response = get_response(request)
  File "/Users/uzair/Dev/GreedyBear/env/lib/python3.9/site-packages/django/core/handlers/base.py", line 181, in _get_response
    response = wrapped_callback(request, *callback_args, **callback_kwargs)
  File "/Users/uzair/Dev/GreedyBear/env/lib/python3.9/site-packages/django/views/decorators/csrf.py", line 54, in wrapped_view
    return view_func(*args, **kwargs)
  File "/Users/uzair/Dev/GreedyBear/env/lib/python3.9/site-packages/django/views/generic/base.py", line 70, in view
    return self.dispatch(request, *args, **kwargs)
  File "/Users/uzair/Dev/GreedyBear/env/lib/python3.9/site-packages/rest_framework/views.py", line 509, in dispatch
    response = self.handle_exception(exc)
  File "/Users/uzair/Dev/GreedyBear/env/lib/python3.9/site-packages/rest_framework/views.py", line 469, in handle_exception
    self.raise_uncaught_exception(exc)
  File "/Users/uzair/Dev/GreedyBear/env/lib/python3.9/site-packages/rest_framework/views.py", line 480, in raise_uncaught_exception
    raise exc
  File "/Users/uzair/Dev/GreedyBear/env/lib/python3.9/site-packages/rest_framework/views.py", line 506, in dispatch
    response = handler(request, *args, **kwargs)
  File "/Users/uzair/Dev/GreedyBear/env/lib/python3.9/site-packages/rest_framework/decorators.py", line 50, in handler
    return func(*args, **kwargs)
  File "/Users/uzair/Dev/GreedyBear/api/views.py", line 153, in enrichment_view
    return Response(serializer.data, status=status.HTTP_200_OK)
  File "/Users/uzair/Dev/GreedyBear/env/lib/python3.9/site-packages/rest_framework/serializers.py", line 555, in data
    ret = super().data
  File "/Users/uzair/Dev/GreedyBear/env/lib/python3.9/site-packages/rest_framework/serializers.py", line 255, in data
    self._data = self.to_representation(self.validated_data)
  File "/Users/uzair/Dev/GreedyBear/env/lib/python3.9/site-packages/rest_framework/serializers.py", line 509, in to_representation
    attribute = field.get_attribute(instance)
  File "/Users/uzair/Dev/GreedyBear/env/lib/python3.9/site-packages/rest_framework/fields.py", line 490, in get_attribute
    raise type(exc)(msg)
AttributeError: Got AttributeError when attempting to get a value for field `query` on serializer `EnrichmentSerializer`.
The serializer field might be named incorrectly and not match any attribute or key on the `IOC` instance.
Original exception text was: 'IOC' object has no attribute 'query'.
2022-02-05 08:08:48,959 - django.server - log_message - ERROR - "GET /api/enrichment?query=140.246.171.141 HTTP/1.1" 500 127198
2022-02-05 08:09:11,552 - django.request - log_response - ERROR - Internal Server Error: /api/enrichment
Traceback (most recent call last):
  File "/Users/uzair/Dev/GreedyBear/env/lib/python3.9/site-packages/rest_framework/fields.py", line 457, in get_attribute
    return get_attribute(instance, self.source_attrs)
  File "/Users/uzair/Dev/GreedyBear/env/lib/python3.9/site-packages/rest_framework/fields.py", line 97, in get_attribute
    instance = getattr(instance, attr)
AttributeError: 'IOC' object has no attribute 'query'

During handling of the above exception, another exception occurred:

Traceback (most recent call last):
  File "/Users/uzair/Dev/GreedyBear/env/lib/python3.9/site-packages/django/core/handlers/exception.py", line 47, in inner
    response = get_response(request)
  File "/Users/uzair/Dev/GreedyBear/env/lib/python3.9/site-packages/django/core/handlers/base.py", line 181, in _get_response
    response = wrapped_callback(request, *callback_args, **callback_kwargs)
  File "/Users/uzair/Dev/GreedyBear/env/lib/python3.9/site-packages/django/views/decorators/csrf.py", line 54, in wrapped_view
    return view_func(*args, **kwargs)
  File "/Users/uzair/Dev/GreedyBear/env/lib/python3.9/site-packages/django/views/generic/base.py", line 70, in view
    return self.dispatch(request, *args, **kwargs)
  File "/Users/uzair/Dev/GreedyBear/env/lib/python3.9/site-packages/rest_framework/views.py", line 509, in dispatch
    response = self.handle_exception(exc)
  File "/Users/uzair/Dev/GreedyBear/env/lib/python3.9/site-packages/rest_framework/views.py", line 469, in handle_exception
    self.raise_uncaught_exception(exc)
  File "/Users/uzair/Dev/GreedyBear/env/lib/python3.9/site-packages/rest_framework/views.py", line 480, in raise_uncaught_exception
    raise exc
  File "/Users/uzair/Dev/GreedyBear/env/lib/python3.9/site-packages/rest_framework/views.py", line 506, in dispatch
    response = handler(request, *args, **kwargs)
  File "/Users/uzair/Dev/GreedyBear/env/lib/python3.9/site-packages/rest_framework/decorators.py", line 50, in handler
    return func(*args, **kwargs)
  File "/Users/uzair/Dev/GreedyBear/api/views.py", line 153, in enrichment_view
    return Response(serializer.data, status=status.HTTP_200_OK)
  File "/Users/uzair/Dev/GreedyBear/env/lib/python3.9/site-packages/rest_framework/serializers.py", line 555, in data
    ret = super().data
  File "/Users/uzair/Dev/GreedyBear/env/lib/python3.9/site-packages/rest_framework/serializers.py", line 255, in data
    self._data = self.to_representation(self.validated_data)
  File "/Users/uzair/Dev/GreedyBear/env/lib/python3.9/site-packages/rest_framework/serializers.py", line 509, in to_representation
    attribute = field.get_attribute(instance)
  File "/Users/uzair/Dev/GreedyBear/env/lib/python3.9/site-packages/rest_framework/fields.py", line 490, in get_attribute
    raise type(exc)(msg)
AttributeError: Got AttributeError when attempting to get a value for field `query` on serializer `EnrichmentSerializer`.
The serializer field might be named incorrectly and not match any attribute or key on the `IOC` instance.
Original exception text was: 'IOC' object has no attribute 'query'.
2022-02-05 08:09:11,554 - django.server - log_message - ERROR - "GET /api/enrichment?query=140.246.171.141 HTTP/1.1" 500 129327
2022-02-05 08:09:53,718 - django.request - log_response - ERROR - Internal Server Error: /api/enrichment
Traceback (most recent call last):
  File "/Users/uzair/Dev/GreedyBear/env/lib/python3.9/site-packages/rest_framework/fields.py", line 457, in get_attribute
    return get_attribute(instance, self.source_attrs)
  File "/Users/uzair/Dev/GreedyBear/env/lib/python3.9/site-packages/rest_framework/fields.py", line 97, in get_attribute
    instance = getattr(instance, attr)
AttributeError: 'IOC' object has no attribute 'query'

During handling of the above exception, another exception occurred:

Traceback (most recent call last):
  File "/Users/uzair/Dev/GreedyBear/env/lib/python3.9/site-packages/django/core/handlers/exception.py", line 47, in inner
    response = get_response(request)
  File "/Users/uzair/Dev/GreedyBear/env/lib/python3.9/site-packages/django/core/handlers/base.py", line 181, in _get_response
    response = wrapped_callback(request, *callback_args, **callback_kwargs)
  File "/Users/uzair/Dev/GreedyBear/env/lib/python3.9/site-packages/django/views/decorators/csrf.py", line 54, in wrapped_view
    return view_func(*args, **kwargs)
  File "/Users/uzair/Dev/GreedyBear/env/lib/python3.9/site-packages/django/views/generic/base.py", line 70, in view
    return self.dispatch(request, *args, **kwargs)
  File "/Users/uzair/Dev/GreedyBear/env/lib/python3.9/site-packages/rest_framework/views.py", line 509, in dispatch
    response = self.handle_exception(exc)
  File "/Users/uzair/Dev/GreedyBear/env/lib/python3.9/site-packages/rest_framework/views.py", line 469, in handle_exception
    self.raise_uncaught_exception(exc)
  File "/Users/uzair/Dev/GreedyBear/env/lib/python3.9/site-packages/rest_framework/views.py", line 480, in raise_uncaught_exception
    raise exc
  File "/Users/uzair/Dev/GreedyBear/env/lib/python3.9/site-packages/rest_framework/views.py", line 506, in dispatch
    response = handler(request, *args, **kwargs)
  File "/Users/uzair/Dev/GreedyBear/env/lib/python3.9/site-packages/rest_framework/decorators.py", line 50, in handler
    return func(*args, **kwargs)
  File "/Users/uzair/Dev/GreedyBear/api/views.py", line 153, in enrichment_view
    return Response(serializer.data, status=status.HTTP_200_OK)
  File "/Users/uzair/Dev/GreedyBear/env/lib/python3.9/site-packages/rest_framework/serializers.py", line 555, in data
    ret = super().data
  File "/Users/uzair/Dev/GreedyBear/env/lib/python3.9/site-packages/rest_framework/serializers.py", line 255, in data
    self._data = self.to_representation(self.validated_data)
  File "/Users/uzair/Dev/GreedyBear/env/lib/python3.9/site-packages/rest_framework/serializers.py", line 509, in to_representation
    attribute = field.get_attribute(instance)
  File "/Users/uzair/Dev/GreedyBear/env/lib/python3.9/site-packages/rest_framework/fields.py", line 490, in get_attribute
    raise type(exc)(msg)
AttributeError: Got AttributeError when attempting to get a value for field `query` on serializer `EnrichmentSerializer`.
The serializer field might be named incorrectly and not match any attribute or key on the `IOC` instance.
Original exception text was: 'IOC' object has no attribute 'query'.
2022-02-05 08:09:53,721 - django.server - log_message - ERROR - "GET /api/enrichment?query=140.246.171.141 HTTP/1.1" 500 127190
2022-02-05 08:09:56,703 - django.request - log_response - ERROR - Internal Server Error: /api/enrichment
Traceback (most recent call last):
  File "/Users/uzair/Dev/GreedyBear/env/lib/python3.9/site-packages/rest_framework/fields.py", line 457, in get_attribute
    return get_attribute(instance, self.source_attrs)
  File "/Users/uzair/Dev/GreedyBear/env/lib/python3.9/site-packages/rest_framework/fields.py", line 97, in get_attribute
    instance = getattr(instance, attr)
AttributeError: 'IOC' object has no attribute 'query'

During handling of the above exception, another exception occurred:

Traceback (most recent call last):
  File "/Users/uzair/Dev/GreedyBear/env/lib/python3.9/site-packages/django/core/handlers/exception.py", line 47, in inner
    response = get_response(request)
  File "/Users/uzair/Dev/GreedyBear/env/lib/python3.9/site-packages/django/core/handlers/base.py", line 181, in _get_response
    response = wrapped_callback(request, *callback_args, **callback_kwargs)
  File "/Users/uzair/Dev/GreedyBear/env/lib/python3.9/site-packages/django/views/decorators/csrf.py", line 54, in wrapped_view
    return view_func(*args, **kwargs)
  File "/Users/uzair/Dev/GreedyBear/env/lib/python3.9/site-packages/django/views/generic/base.py", line 70, in view
    return self.dispatch(request, *args, **kwargs)
  File "/Users/uzair/Dev/GreedyBear/env/lib/python3.9/site-packages/rest_framework/views.py", line 509, in dispatch
    response = self.handle_exception(exc)
  File "/Users/uzair/Dev/GreedyBear/env/lib/python3.9/site-packages/rest_framework/views.py", line 469, in handle_exception
    self.raise_uncaught_exception(exc)
  File "/Users/uzair/Dev/GreedyBear/env/lib/python3.9/site-packages/rest_framework/views.py", line 480, in raise_uncaught_exception
    raise exc
  File "/Users/uzair/Dev/GreedyBear/env/lib/python3.9/site-packages/rest_framework/views.py", line 506, in dispatch
    response = handler(request, *args, **kwargs)
  File "/Users/uzair/Dev/GreedyBear/env/lib/python3.9/site-packages/rest_framework/decorators.py", line 50, in handler
    return func(*args, **kwargs)
  File "/Users/uzair/Dev/GreedyBear/api/views.py", line 153, in enrichment_view
    return Response(serializer.data, status=status.HTTP_200_OK)
  File "/Users/uzair/Dev/GreedyBear/env/lib/python3.9/site-packages/rest_framework/serializers.py", line 555, in data
    ret = super().data
  File "/Users/uzair/Dev/GreedyBear/env/lib/python3.9/site-packages/rest_framework/serializers.py", line 255, in data
    self._data = self.to_representation(self.validated_data)
  File "/Users/uzair/Dev/GreedyBear/env/lib/python3.9/site-packages/rest_framework/serializers.py", line 509, in to_representation
    attribute = field.get_attribute(instance)
  File "/Users/uzair/Dev/GreedyBear/env/lib/python3.9/site-packages/rest_framework/fields.py", line 490, in get_attribute
    raise type(exc)(msg)
AttributeError: Got AttributeError when attempting to get a value for field `query` on serializer `EnrichmentSerializer`.
The serializer field might be named incorrectly and not match any attribute or key on the `IOC` instance.
Original exception text was: 'IOC' object has no attribute 'query'.
2022-02-05 08:09:56,704 - django.server - log_message - ERROR - "GET /api/enrichment?query=140.246.171.141 HTTP/1.1" 500 129464
2022-02-05 08:14:26,368 - django.request - log_response - ERROR - Internal Server Error: /api/enrichment
Traceback (most recent call last):
  File "/Users/uzair/Dev/GreedyBear/env/lib/python3.9/site-packages/rest_framework/fields.py", line 457, in get_attribute
    return get_attribute(instance, self.source_attrs)
  File "/Users/uzair/Dev/GreedyBear/env/lib/python3.9/site-packages/rest_framework/fields.py", line 97, in get_attribute
    instance = getattr(instance, attr)
AttributeError: 'IOC' object has no attribute 'query'

During handling of the above exception, another exception occurred:

Traceback (most recent call last):
  File "/Users/uzair/Dev/GreedyBear/env/lib/python3.9/site-packages/django/core/handlers/exception.py", line 47, in inner
    response = get_response(request)
  File "/Users/uzair/Dev/GreedyBear/env/lib/python3.9/site-packages/django/core/handlers/base.py", line 181, in _get_response
    response = wrapped_callback(request, *callback_args, **callback_kwargs)
  File "/Users/uzair/Dev/GreedyBear/env/lib/python3.9/site-packages/django/views/decorators/csrf.py", line 54, in wrapped_view
    return view_func(*args, **kwargs)
  File "/Users/uzair/Dev/GreedyBear/env/lib/python3.9/site-packages/django/views/generic/base.py", line 70, in view
    return self.dispatch(request, *args, **kwargs)
  File "/Users/uzair/Dev/GreedyBear/env/lib/python3.9/site-packages/rest_framework/views.py", line 509, in dispatch
    response = self.handle_exception(exc)
  File "/Users/uzair/Dev/GreedyBear/env/lib/python3.9/site-packages/rest_framework/views.py", line 469, in handle_exception
    self.raise_uncaught_exception(exc)
  File "/Users/uzair/Dev/GreedyBear/env/lib/python3.9/site-packages/rest_framework/views.py", line 480, in raise_uncaught_exception
    raise exc
  File "/Users/uzair/Dev/GreedyBear/env/lib/python3.9/site-packages/rest_framework/views.py", line 506, in dispatch
    response = handler(request, *args, **kwargs)
  File "/Users/uzair/Dev/GreedyBear/env/lib/python3.9/site-packages/rest_framework/decorators.py", line 50, in handler
    return func(*args, **kwargs)
  File "/Users/uzair/Dev/GreedyBear/api/views.py", line 153, in enrichment_view
    return Response(serializer.data, status=status.HTTP_200_OK)
  File "/Users/uzair/Dev/GreedyBear/env/lib/python3.9/site-packages/rest_framework/serializers.py", line 555, in data
    ret = super().data
  File "/Users/uzair/Dev/GreedyBear/env/lib/python3.9/site-packages/rest_framework/serializers.py", line 255, in data
    self._data = self.to_representation(self.validated_data)
  File "/Users/uzair/Dev/GreedyBear/env/lib/python3.9/site-packages/rest_framework/serializers.py", line 509, in to_representation
    attribute = field.get_attribute(instance)
  File "/Users/uzair/Dev/GreedyBear/env/lib/python3.9/site-packages/rest_framework/fields.py", line 490, in get_attribute
    raise type(exc)(msg)
AttributeError: Got AttributeError when attempting to get a value for field `query` on serializer `EnrichmentSerializer`.
The serializer field might be named incorrectly and not match any attribute or key on the `IOC` instance.
Original exception text was: 'IOC' object has no attribute 'query'.
2022-02-05 08:14:26,372 - django.server - log_message - ERROR - "GET /api/enrichment?query=140.246.171.141 HTTP/1.1" 500 127190
2022-02-05 08:15:06,572 - django.request - log_response - ERROR - Internal Server Error: /api/enrichment
Traceback (most recent call last):
  File "/Users/uzair/Dev/GreedyBear/env/lib/python3.9/site-packages/rest_framework/fields.py", line 457, in get_attribute
    return get_attribute(instance, self.source_attrs)
  File "/Users/uzair/Dev/GreedyBear/env/lib/python3.9/site-packages/rest_framework/fields.py", line 97, in get_attribute
    instance = getattr(instance, attr)
AttributeError: 'IOC' object has no attribute 'query'

During handling of the above exception, another exception occurred:

Traceback (most recent call last):
  File "/Users/uzair/Dev/GreedyBear/env/lib/python3.9/site-packages/django/core/handlers/exception.py", line 47, in inner
    response = get_response(request)
  File "/Users/uzair/Dev/GreedyBear/env/lib/python3.9/site-packages/django/core/handlers/base.py", line 181, in _get_response
    response = wrapped_callback(request, *callback_args, **callback_kwargs)
  File "/Users/uzair/Dev/GreedyBear/env/lib/python3.9/site-packages/django/views/decorators/csrf.py", line 54, in wrapped_view
    return view_func(*args, **kwargs)
  File "/Users/uzair/Dev/GreedyBear/env/lib/python3.9/site-packages/django/views/generic/base.py", line 70, in view
    return self.dispatch(request, *args, **kwargs)
  File "/Users/uzair/Dev/GreedyBear/env/lib/python3.9/site-packages/rest_framework/views.py", line 509, in dispatch
    response = self.handle_exception(exc)
  File "/Users/uzair/Dev/GreedyBear/env/lib/python3.9/site-packages/rest_framework/views.py", line 469, in handle_exception
    self.raise_uncaught_exception(exc)
  File "/Users/uzair/Dev/GreedyBear/env/lib/python3.9/site-packages/rest_framework/views.py", line 480, in raise_uncaught_exception
    raise exc
  File "/Users/uzair/Dev/GreedyBear/env/lib/python3.9/site-packages/rest_framework/views.py", line 506, in dispatch
    response = handler(request, *args, **kwargs)
  File "/Users/uzair/Dev/GreedyBear/env/lib/python3.9/site-packages/rest_framework/decorators.py", line 50, in handler
    return func(*args, **kwargs)
  File "/Users/uzair/Dev/GreedyBear/api/views.py", line 153, in enrichment_view
    return Response(serializer.data, status=status.HTTP_200_OK)
  File "/Users/uzair/Dev/GreedyBear/env/lib/python3.9/site-packages/rest_framework/serializers.py", line 555, in data
    ret = super().data
  File "/Users/uzair/Dev/GreedyBear/env/lib/python3.9/site-packages/rest_framework/serializers.py", line 255, in data
    self._data = self.to_representation(self.validated_data)
  File "/Users/uzair/Dev/GreedyBear/env/lib/python3.9/site-packages/rest_framework/serializers.py", line 509, in to_representation
    attribute = field.get_attribute(instance)
  File "/Users/uzair/Dev/GreedyBear/env/lib/python3.9/site-packages/rest_framework/fields.py", line 490, in get_attribute
    raise type(exc)(msg)
AttributeError: Got AttributeError when attempting to get a value for field `query` on serializer `EnrichmentSerializer`.
The serializer field might be named incorrectly and not match any attribute or key on the `IOC` instance.
Original exception text was: 'IOC' object has no attribute 'query'.
2022-02-05 08:15:06,573 - django.server - log_message - ERROR - "GET /api/enrichment?query=140.246.171.141 HTTP/1.1" 500 129327
2022-02-05 08:15:54,392 - django.request - log_response - ERROR - Internal Server Error: /api/enrichment
Traceback (most recent call last):
  File "/Users/uzair/Dev/GreedyBear/env/lib/python3.9/site-packages/rest_framework/fields.py", line 457, in get_attribute
    return get_attribute(instance, self.source_attrs)
  File "/Users/uzair/Dev/GreedyBear/env/lib/python3.9/site-packages/rest_framework/fields.py", line 97, in get_attribute
    instance = getattr(instance, attr)
AttributeError: 'IOC' object has no attribute 'query'

During handling of the above exception, another exception occurred:

Traceback (most recent call last):
  File "/Users/uzair/Dev/GreedyBear/env/lib/python3.9/site-packages/django/core/handlers/exception.py", line 47, in inner
    response = get_response(request)
  File "/Users/uzair/Dev/GreedyBear/env/lib/python3.9/site-packages/django/core/handlers/base.py", line 181, in _get_response
    response = wrapped_callback(request, *callback_args, **callback_kwargs)
  File "/Users/uzair/Dev/GreedyBear/env/lib/python3.9/site-packages/django/views/decorators/csrf.py", line 54, in wrapped_view
    return view_func(*args, **kwargs)
  File "/Users/uzair/Dev/GreedyBear/env/lib/python3.9/site-packages/django/views/generic/base.py", line 70, in view
    return self.dispatch(request, *args, **kwargs)
  File "/Users/uzair/Dev/GreedyBear/env/lib/python3.9/site-packages/rest_framework/views.py", line 509, in dispatch
    response = self.handle_exception(exc)
  File "/Users/uzair/Dev/GreedyBear/env/lib/python3.9/site-packages/rest_framework/views.py", line 469, in handle_exception
    self.raise_uncaught_exception(exc)
  File "/Users/uzair/Dev/GreedyBear/env/lib/python3.9/site-packages/rest_framework/views.py", line 480, in raise_uncaught_exception
    raise exc
  File "/Users/uzair/Dev/GreedyBear/env/lib/python3.9/site-packages/rest_framework/views.py", line 506, in dispatch
    response = handler(request, *args, **kwargs)
  File "/Users/uzair/Dev/GreedyBear/env/lib/python3.9/site-packages/rest_framework/decorators.py", line 50, in handler
    return func(*args, **kwargs)
  File "/Users/uzair/Dev/GreedyBear/api/views.py", line 153, in enrichment_view
    return Response(serializer.data, status=status.HTTP_200_OK)
  File "/Users/uzair/Dev/GreedyBear/env/lib/python3.9/site-packages/rest_framework/serializers.py", line 555, in data
    ret = super().data
  File "/Users/uzair/Dev/GreedyBear/env/lib/python3.9/site-packages/rest_framework/serializers.py", line 255, in data
    self._data = self.to_representation(self.validated_data)
  File "/Users/uzair/Dev/GreedyBear/env/lib/python3.9/site-packages/rest_framework/serializers.py", line 509, in to_representation
    attribute = field.get_attribute(instance)
  File "/Users/uzair/Dev/GreedyBear/env/lib/python3.9/site-packages/rest_framework/fields.py", line 490, in get_attribute
    raise type(exc)(msg)
AttributeError: Got AttributeError when attempting to get a value for field `query` on serializer `EnrichmentSerializer`.
The serializer field might be named incorrectly and not match any attribute or key on the `IOC` instance.
Original exception text was: 'IOC' object has no attribute 'query'.
2022-02-05 08:15:54,393 - django.server - log_message - ERROR - "GET /api/enrichment?query=140.246.171.141 HTTP/1.1" 500 127190
2022-02-05 08:16:20,970 - django.request - log_response - ERROR - Internal Server Error: /api/enrichment
Traceback (most recent call last):
  File "/Users/uzair/Dev/GreedyBear/env/lib/python3.9/site-packages/rest_framework/fields.py", line 457, in get_attribute
    return get_attribute(instance, self.source_attrs)
  File "/Users/uzair/Dev/GreedyBear/env/lib/python3.9/site-packages/rest_framework/fields.py", line 97, in get_attribute
    instance = getattr(instance, attr)
AttributeError: 'IOC' object has no attribute 'query'

During handling of the above exception, another exception occurred:

Traceback (most recent call last):
  File "/Users/uzair/Dev/GreedyBear/env/lib/python3.9/site-packages/django/core/handlers/exception.py", line 47, in inner
    response = get_response(request)
  File "/Users/uzair/Dev/GreedyBear/env/lib/python3.9/site-packages/django/core/handlers/base.py", line 181, in _get_response
    response = wrapped_callback(request, *callback_args, **callback_kwargs)
  File "/Users/uzair/Dev/GreedyBear/env/lib/python3.9/site-packages/django/views/decorators/csrf.py", line 54, in wrapped_view
    return view_func(*args, **kwargs)
  File "/Users/uzair/Dev/GreedyBear/env/lib/python3.9/site-packages/django/views/generic/base.py", line 70, in view
    return self.dispatch(request, *args, **kwargs)
  File "/Users/uzair/Dev/GreedyBear/env/lib/python3.9/site-packages/rest_framework/views.py", line 509, in dispatch
    response = self.handle_exception(exc)
  File "/Users/uzair/Dev/GreedyBear/env/lib/python3.9/site-packages/rest_framework/views.py", line 469, in handle_exception
    self.raise_uncaught_exception(exc)
  File "/Users/uzair/Dev/GreedyBear/env/lib/python3.9/site-packages/rest_framework/views.py", line 480, in raise_uncaught_exception
    raise exc
  File "/Users/uzair/Dev/GreedyBear/env/lib/python3.9/site-packages/rest_framework/views.py", line 506, in dispatch
    response = handler(request, *args, **kwargs)
  File "/Users/uzair/Dev/GreedyBear/env/lib/python3.9/site-packages/rest_framework/decorators.py", line 50, in handler
    return func(*args, **kwargs)
  File "/Users/uzair/Dev/GreedyBear/api/views.py", line 153, in enrichment_view
    return Response(serializer.data, status=status.HTTP_200_OK)
  File "/Users/uzair/Dev/GreedyBear/env/lib/python3.9/site-packages/rest_framework/serializers.py", line 555, in data
    ret = super().data
  File "/Users/uzair/Dev/GreedyBear/env/lib/python3.9/site-packages/rest_framework/serializers.py", line 255, in data
    self._data = self.to_representation(self.validated_data)
  File "/Users/uzair/Dev/GreedyBear/env/lib/python3.9/site-packages/rest_framework/serializers.py", line 509, in to_representation
    attribute = field.get_attribute(instance)
  File "/Users/uzair/Dev/GreedyBear/env/lib/python3.9/site-packages/rest_framework/fields.py", line 490, in get_attribute
    raise type(exc)(msg)
AttributeError: Got AttributeError when attempting to get a value for field `query` on serializer `EnrichmentSerializer`.
The serializer field might be named incorrectly and not match any attribute or key on the `IOC` instance.
Original exception text was: 'IOC' object has no attribute 'query'.
2022-02-05 08:16:20,972 - django.server - log_message - ERROR - "GET /api/enrichment?query=140.246.171.141 HTTP/1.1" 500 127190
2022-02-05 08:20:49,621 - django.request - log_response - ERROR - Internal Server Error: /api/enrichment
Traceback (most recent call last):
  File "/Users/uzair/Dev/GreedyBear/env/lib/python3.9/site-packages/rest_framework/fields.py", line 457, in get_attribute
    return get_attribute(instance, self.source_attrs)
  File "/Users/uzair/Dev/GreedyBear/env/lib/python3.9/site-packages/rest_framework/fields.py", line 97, in get_attribute
    instance = getattr(instance, attr)
AttributeError: 'IOC' object has no attribute 'query'

During handling of the above exception, another exception occurred:

Traceback (most recent call last):
  File "/Users/uzair/Dev/GreedyBear/env/lib/python3.9/site-packages/django/core/handlers/exception.py", line 47, in inner
    response = get_response(request)
  File "/Users/uzair/Dev/GreedyBear/env/lib/python3.9/site-packages/django/core/handlers/base.py", line 181, in _get_response
    response = wrapped_callback(request, *callback_args, **callback_kwargs)
  File "/Users/uzair/Dev/GreedyBear/env/lib/python3.9/site-packages/django/views/decorators/csrf.py", line 54, in wrapped_view
    return view_func(*args, **kwargs)
  File "/Users/uzair/Dev/GreedyBear/env/lib/python3.9/site-packages/django/views/generic/base.py", line 70, in view
    return self.dispatch(request, *args, **kwargs)
  File "/Users/uzair/Dev/GreedyBear/env/lib/python3.9/site-packages/rest_framework/views.py", line 509, in dispatch
    response = self.handle_exception(exc)
  File "/Users/uzair/Dev/GreedyBear/env/lib/python3.9/site-packages/rest_framework/views.py", line 469, in handle_exception
    self.raise_uncaught_exception(exc)
  File "/Users/uzair/Dev/GreedyBear/env/lib/python3.9/site-packages/rest_framework/views.py", line 480, in raise_uncaught_exception
    raise exc
  File "/Users/uzair/Dev/GreedyBear/env/lib/python3.9/site-packages/rest_framework/views.py", line 506, in dispatch
    response = handler(request, *args, **kwargs)
  File "/Users/uzair/Dev/GreedyBear/env/lib/python3.9/site-packages/rest_framework/decorators.py", line 50, in handler
    return func(*args, **kwargs)
  File "/Users/uzair/Dev/GreedyBear/api/views.py", line 153, in enrichment_view
    return Response(serializer.data, status=status.HTTP_200_OK)
  File "/Users/uzair/Dev/GreedyBear/env/lib/python3.9/site-packages/rest_framework/serializers.py", line 555, in data
    ret = super().data
  File "/Users/uzair/Dev/GreedyBear/env/lib/python3.9/site-packages/rest_framework/serializers.py", line 255, in data
    self._data = self.to_representation(self.validated_data)
  File "/Users/uzair/Dev/GreedyBear/env/lib/python3.9/site-packages/rest_framework/serializers.py", line 509, in to_representation
    attribute = field.get_attribute(instance)
  File "/Users/uzair/Dev/GreedyBear/env/lib/python3.9/site-packages/rest_framework/fields.py", line 490, in get_attribute
    raise type(exc)(msg)
AttributeError: Got AttributeError when attempting to get a value for field `query` on serializer `EnrichmentSerializer`.
The serializer field might be named incorrectly and not match any attribute or key on the `IOC` instance.
Original exception text was: 'IOC' object has no attribute 'query'.
2022-02-05 08:20:49,627 - django.server - log_message - ERROR - "GET /api/enrichment?query=140.246.171.141 HTTP/1.1" 500 127201
2022-02-05 08:20:50,921 - django.request - log_response - ERROR - Internal Server Error: /api/enrichment
Traceback (most recent call last):
  File "/Users/uzair/Dev/GreedyBear/env/lib/python3.9/site-packages/rest_framework/fields.py", line 457, in get_attribute
    return get_attribute(instance, self.source_attrs)
  File "/Users/uzair/Dev/GreedyBear/env/lib/python3.9/site-packages/rest_framework/fields.py", line 97, in get_attribute
    instance = getattr(instance, attr)
AttributeError: 'IOC' object has no attribute 'query'

During handling of the above exception, another exception occurred:

Traceback (most recent call last):
  File "/Users/uzair/Dev/GreedyBear/env/lib/python3.9/site-packages/django/core/handlers/exception.py", line 47, in inner
    response = get_response(request)
  File "/Users/uzair/Dev/GreedyBear/env/lib/python3.9/site-packages/django/core/handlers/base.py", line 181, in _get_response
    response = wrapped_callback(request, *callback_args, **callback_kwargs)
  File "/Users/uzair/Dev/GreedyBear/env/lib/python3.9/site-packages/django/views/decorators/csrf.py", line 54, in wrapped_view
    return view_func(*args, **kwargs)
  File "/Users/uzair/Dev/GreedyBear/env/lib/python3.9/site-packages/django/views/generic/base.py", line 70, in view
    return self.dispatch(request, *args, **kwargs)
  File "/Users/uzair/Dev/GreedyBear/env/lib/python3.9/site-packages/rest_framework/views.py", line 509, in dispatch
    response = self.handle_exception(exc)
  File "/Users/uzair/Dev/GreedyBear/env/lib/python3.9/site-packages/rest_framework/views.py", line 469, in handle_exception
    self.raise_uncaught_exception(exc)
  File "/Users/uzair/Dev/GreedyBear/env/lib/python3.9/site-packages/rest_framework/views.py", line 480, in raise_uncaught_exception
    raise exc
  File "/Users/uzair/Dev/GreedyBear/env/lib/python3.9/site-packages/rest_framework/views.py", line 506, in dispatch
    response = handler(request, *args, **kwargs)
  File "/Users/uzair/Dev/GreedyBear/env/lib/python3.9/site-packages/rest_framework/decorators.py", line 50, in handler
    return func(*args, **kwargs)
  File "/Users/uzair/Dev/GreedyBear/api/views.py", line 153, in enrichment_view
    return Response(serializer.data, status=status.HTTP_200_OK)
  File "/Users/uzair/Dev/GreedyBear/env/lib/python3.9/site-packages/rest_framework/serializers.py", line 555, in data
    ret = super().data
  File "/Users/uzair/Dev/GreedyBear/env/lib/python3.9/site-packages/rest_framework/serializers.py", line 255, in data
    self._data = self.to_representation(self.validated_data)
  File "/Users/uzair/Dev/GreedyBear/env/lib/python3.9/site-packages/rest_framework/serializers.py", line 509, in to_representation
    attribute = field.get_attribute(instance)
  File "/Users/uzair/Dev/GreedyBear/env/lib/python3.9/site-packages/rest_framework/fields.py", line 490, in get_attribute
    raise type(exc)(msg)
AttributeError: Got AttributeError when attempting to get a value for field `query` on serializer `EnrichmentSerializer`.
The serializer field might be named incorrectly and not match any attribute or key on the `IOC` instance.
Original exception text was: 'IOC' object has no attribute 'query'.
2022-02-05 08:20:50,922 - django.server - log_message - ERROR - "GET /api/enrichment?query=140.246.171.141 HTTP/1.1" 500 127201
2022-02-05 08:20:56,140 - django.request - log_response - ERROR - Internal Server Error: /api/enrichment
Traceback (most recent call last):
  File "/Users/uzair/Dev/GreedyBear/env/lib/python3.9/site-packages/rest_framework/fields.py", line 457, in get_attribute
    return get_attribute(instance, self.source_attrs)
  File "/Users/uzair/Dev/GreedyBear/env/lib/python3.9/site-packages/rest_framework/fields.py", line 97, in get_attribute
    instance = getattr(instance, attr)
AttributeError: 'IOC' object has no attribute 'query'

During handling of the above exception, another exception occurred:

Traceback (most recent call last):
  File "/Users/uzair/Dev/GreedyBear/env/lib/python3.9/site-packages/django/core/handlers/exception.py", line 47, in inner
    response = get_response(request)
  File "/Users/uzair/Dev/GreedyBear/env/lib/python3.9/site-packages/django/core/handlers/base.py", line 181, in _get_response
    response = wrapped_callback(request, *callback_args, **callback_kwargs)
  File "/Users/uzair/Dev/GreedyBear/env/lib/python3.9/site-packages/django/views/decorators/csrf.py", line 54, in wrapped_view
    return view_func(*args, **kwargs)
  File "/Users/uzair/Dev/GreedyBear/env/lib/python3.9/site-packages/django/views/generic/base.py", line 70, in view
    return self.dispatch(request, *args, **kwargs)
  File "/Users/uzair/Dev/GreedyBear/env/lib/python3.9/site-packages/rest_framework/views.py", line 509, in dispatch
    response = self.handle_exception(exc)
  File "/Users/uzair/Dev/GreedyBear/env/lib/python3.9/site-packages/rest_framework/views.py", line 469, in handle_exception
    self.raise_uncaught_exception(exc)
  File "/Users/uzair/Dev/GreedyBear/env/lib/python3.9/site-packages/rest_framework/views.py", line 480, in raise_uncaught_exception
    raise exc
  File "/Users/uzair/Dev/GreedyBear/env/lib/python3.9/site-packages/rest_framework/views.py", line 506, in dispatch
    response = handler(request, *args, **kwargs)
  File "/Users/uzair/Dev/GreedyBear/env/lib/python3.9/site-packages/rest_framework/decorators.py", line 50, in handler
    return func(*args, **kwargs)
  File "/Users/uzair/Dev/GreedyBear/api/views.py", line 153, in enrichment_view
    return Response(serializer.data, status=status.HTTP_200_OK)
  File "/Users/uzair/Dev/GreedyBear/env/lib/python3.9/site-packages/rest_framework/serializers.py", line 555, in data
    ret = super().data
  File "/Users/uzair/Dev/GreedyBear/env/lib/python3.9/site-packages/rest_framework/serializers.py", line 255, in data
    self._data = self.to_representation(self.validated_data)
  File "/Users/uzair/Dev/GreedyBear/env/lib/python3.9/site-packages/rest_framework/serializers.py", line 509, in to_representation
    attribute = field.get_attribute(instance)
  File "/Users/uzair/Dev/GreedyBear/env/lib/python3.9/site-packages/rest_framework/fields.py", line 490, in get_attribute
    raise type(exc)(msg)
AttributeError: Got AttributeError when attempting to get a value for field `query` on serializer `EnrichmentSerializer`.
The serializer field might be named incorrectly and not match any attribute or key on the `IOC` instance.
Original exception text was: 'IOC' object has no attribute 'query'.
2022-02-05 08:20:56,140 - django.server - log_message - ERROR - "GET /api/enrichment?query=140.246.171.141 HTTP/1.1" 500 129475
2022-02-05 08:20:59,126 - django.request - log_response - ERROR - Internal Server Error: /api/enrichment
Traceback (most recent call last):
  File "/Users/uzair/Dev/GreedyBear/env/lib/python3.9/site-packages/rest_framework/fields.py", line 457, in get_attribute
    return get_attribute(instance, self.source_attrs)
  File "/Users/uzair/Dev/GreedyBear/env/lib/python3.9/site-packages/rest_framework/fields.py", line 97, in get_attribute
    instance = getattr(instance, attr)
AttributeError: 'IOC' object has no attribute 'query'

During handling of the above exception, another exception occurred:

Traceback (most recent call last):
  File "/Users/uzair/Dev/GreedyBear/env/lib/python3.9/site-packages/django/core/handlers/exception.py", line 47, in inner
    response = get_response(request)
  File "/Users/uzair/Dev/GreedyBear/env/lib/python3.9/site-packages/django/core/handlers/base.py", line 181, in _get_response
    response = wrapped_callback(request, *callback_args, **callback_kwargs)
  File "/Users/uzair/Dev/GreedyBear/env/lib/python3.9/site-packages/django/views/decorators/csrf.py", line 54, in wrapped_view
    return view_func(*args, **kwargs)
  File "/Users/uzair/Dev/GreedyBear/env/lib/python3.9/site-packages/django/views/generic/base.py", line 70, in view
    return self.dispatch(request, *args, **kwargs)
  File "/Users/uzair/Dev/GreedyBear/env/lib/python3.9/site-packages/rest_framework/views.py", line 509, in dispatch
    response = self.handle_exception(exc)
  File "/Users/uzair/Dev/GreedyBear/env/lib/python3.9/site-packages/rest_framework/views.py", line 469, in handle_exception
    self.raise_uncaught_exception(exc)
  File "/Users/uzair/Dev/GreedyBear/env/lib/python3.9/site-packages/rest_framework/views.py", line 480, in raise_uncaught_exception
    raise exc
  File "/Users/uzair/Dev/GreedyBear/env/lib/python3.9/site-packages/rest_framework/views.py", line 506, in dispatch
    response = handler(request, *args, **kwargs)
  File "/Users/uzair/Dev/GreedyBear/env/lib/python3.9/site-packages/rest_framework/decorators.py", line 50, in handler
    return func(*args, **kwargs)
  File "/Users/uzair/Dev/GreedyBear/api/views.py", line 153, in enrichment_view
    return Response(serializer.data, status=status.HTTP_200_OK)
  File "/Users/uzair/Dev/GreedyBear/env/lib/python3.9/site-packages/rest_framework/serializers.py", line 555, in data
    ret = super().data
  File "/Users/uzair/Dev/GreedyBear/env/lib/python3.9/site-packages/rest_framework/serializers.py", line 255, in data
    self._data = self.to_representation(self.validated_data)
  File "/Users/uzair/Dev/GreedyBear/env/lib/python3.9/site-packages/rest_framework/serializers.py", line 509, in to_representation
    attribute = field.get_attribute(instance)
  File "/Users/uzair/Dev/GreedyBear/env/lib/python3.9/site-packages/rest_framework/fields.py", line 490, in get_attribute
    raise type(exc)(msg)
AttributeError: Got AttributeError when attempting to get a value for field `query` on serializer `EnrichmentSerializer`.
The serializer field might be named incorrectly and not match any attribute or key on the `IOC` instance.
Original exception text was: 'IOC' object has no attribute 'query'.
2022-02-05 08:20:59,126 - django.server - log_message - ERROR - "GET /api/enrichment?query=140.246.171.141 HTTP/1.1" 500 129475
2022-02-05 08:25:55,302 - django.request - log_response - ERROR - Internal Server Error: /api/enrichment
Traceback (most recent call last):
  File "/Users/uzair/Dev/GreedyBear/env/lib/python3.9/site-packages/django/core/handlers/exception.py", line 47, in inner
    response = get_response(request)
  File "/Users/uzair/Dev/GreedyBear/env/lib/python3.9/site-packages/django/core/handlers/base.py", line 181, in _get_response
    response = wrapped_callback(request, *callback_args, **callback_kwargs)
  File "/Users/uzair/Dev/GreedyBear/env/lib/python3.9/site-packages/django/views/decorators/csrf.py", line 54, in wrapped_view
    return view_func(*args, **kwargs)
  File "/Users/uzair/Dev/GreedyBear/env/lib/python3.9/site-packages/django/views/generic/base.py", line 70, in view
    return self.dispatch(request, *args, **kwargs)
  File "/Users/uzair/Dev/GreedyBear/env/lib/python3.9/site-packages/rest_framework/views.py", line 509, in dispatch
    response = self.handle_exception(exc)
  File "/Users/uzair/Dev/GreedyBear/env/lib/python3.9/site-packages/rest_framework/views.py", line 469, in handle_exception
    self.raise_uncaught_exception(exc)
  File "/Users/uzair/Dev/GreedyBear/env/lib/python3.9/site-packages/rest_framework/views.py", line 480, in raise_uncaught_exception
    raise exc
  File "/Users/uzair/Dev/GreedyBear/env/lib/python3.9/site-packages/rest_framework/views.py", line 506, in dispatch
    response = handler(request, *args, **kwargs)
  File "/Users/uzair/Dev/GreedyBear/env/lib/python3.9/site-packages/rest_framework/decorators.py", line 50, in handler
    return func(*args, **kwargs)
  File "/Users/uzair/Dev/GreedyBear/api/views.py", line 153, in enrichment_view
    return Response(serializer.data, status=status.HTTP_200_OK)
  File "/Users/uzair/Dev/GreedyBear/env/lib/python3.9/site-packages/rest_framework/serializers.py", line 555, in data
    ret = super().data
  File "/Users/uzair/Dev/GreedyBear/env/lib/python3.9/site-packages/rest_framework/serializers.py", line 255, in data
    self._data = self.to_representation(self.validated_data)
  File "/Users/uzair/Dev/GreedyBear/env/lib/python3.9/site-packages/rest_framework/serializers.py", line 522, in to_representation
    ret[field.field_name] = field.to_representation(attribute)
  File "/Users/uzair/Dev/GreedyBear/env/lib/python3.9/site-packages/rest_framework/serializers.py", line 507, in to_representation
    for field in fields:
  File "/Users/uzair/Dev/GreedyBear/env/lib/python3.9/site-packages/rest_framework/serializers.py", line 368, in _readable_fields
    for field in self.fields.values():
  File "/Users/uzair/Dev/GreedyBear/env/lib/python3.9/site-packages/django/utils/functional.py", line 48, in __get__
    res = instance.__dict__[self.name] = self.func(instance)
  File "/Users/uzair/Dev/GreedyBear/env/lib/python3.9/site-packages/rest_framework/serializers.py", line 356, in fields
    for key, value in self.get_fields().items():
  File "/Users/uzair/Dev/GreedyBear/env/lib/python3.9/site-packages/rest_framework/serializers.py", line 1052, in get_fields
    field_names = self.get_field_names(declared_fields, info)
  File "/Users/uzair/Dev/GreedyBear/env/lib/python3.9/site-packages/rest_framework/serializers.py", line 1124, in get_field_names
    assert not (fields is None and exclude is None), (
AssertionError: ("Creating a ModelSerializer without either the 'fields' attribute or the 'exclude' attribute has been deprecated since 3.3.0, and is now disallowed. Add an explicit fields = '__all__' to the IOCSerializer serializer.",)
2022-02-05 08:25:55,304 - django.server - log_message - ERROR - "GET /api/enrichment?query=140.246.171.141 HTTP/1.1" 500 146241
2022-02-05 08:25:56,773 - django.request - log_response - ERROR - Internal Server Error: /api/enrichment
Traceback (most recent call last):
  File "/Users/uzair/Dev/GreedyBear/env/lib/python3.9/site-packages/django/core/handlers/exception.py", line 47, in inner
    response = get_response(request)
  File "/Users/uzair/Dev/GreedyBear/env/lib/python3.9/site-packages/django/core/handlers/base.py", line 181, in _get_response
    response = wrapped_callback(request, *callback_args, **callback_kwargs)
  File "/Users/uzair/Dev/GreedyBear/env/lib/python3.9/site-packages/django/views/decorators/csrf.py", line 54, in wrapped_view
    return view_func(*args, **kwargs)
  File "/Users/uzair/Dev/GreedyBear/env/lib/python3.9/site-packages/django/views/generic/base.py", line 70, in view
    return self.dispatch(request, *args, **kwargs)
  File "/Users/uzair/Dev/GreedyBear/env/lib/python3.9/site-packages/rest_framework/views.py", line 509, in dispatch
    response = self.handle_exception(exc)
  File "/Users/uzair/Dev/GreedyBear/env/lib/python3.9/site-packages/rest_framework/views.py", line 469, in handle_exception
    self.raise_uncaught_exception(exc)
  File "/Users/uzair/Dev/GreedyBear/env/lib/python3.9/site-packages/rest_framework/views.py", line 480, in raise_uncaught_exception
    raise exc
  File "/Users/uzair/Dev/GreedyBear/env/lib/python3.9/site-packages/rest_framework/views.py", line 506, in dispatch
    response = handler(request, *args, **kwargs)
  File "/Users/uzair/Dev/GreedyBear/env/lib/python3.9/site-packages/rest_framework/decorators.py", line 50, in handler
    return func(*args, **kwargs)
  File "/Users/uzair/Dev/GreedyBear/api/views.py", line 153, in enrichment_view
    return Response(serializer.data, status=status.HTTP_200_OK)
  File "/Users/uzair/Dev/GreedyBear/env/lib/python3.9/site-packages/rest_framework/serializers.py", line 555, in data
    ret = super().data
  File "/Users/uzair/Dev/GreedyBear/env/lib/python3.9/site-packages/rest_framework/serializers.py", line 255, in data
    self._data = self.to_representation(self.validated_data)
  File "/Users/uzair/Dev/GreedyBear/env/lib/python3.9/site-packages/rest_framework/serializers.py", line 522, in to_representation
    ret[field.field_name] = field.to_representation(attribute)
  File "/Users/uzair/Dev/GreedyBear/env/lib/python3.9/site-packages/rest_framework/serializers.py", line 507, in to_representation
    for field in fields:
  File "/Users/uzair/Dev/GreedyBear/env/lib/python3.9/site-packages/rest_framework/serializers.py", line 368, in _readable_fields
    for field in self.fields.values():
  File "/Users/uzair/Dev/GreedyBear/env/lib/python3.9/site-packages/django/utils/functional.py", line 48, in __get__
    res = instance.__dict__[self.name] = self.func(instance)
  File "/Users/uzair/Dev/GreedyBear/env/lib/python3.9/site-packages/rest_framework/serializers.py", line 356, in fields
    for key, value in self.get_fields().items():
  File "/Users/uzair/Dev/GreedyBear/env/lib/python3.9/site-packages/rest_framework/serializers.py", line 1052, in get_fields
    field_names = self.get_field_names(declared_fields, info)
  File "/Users/uzair/Dev/GreedyBear/env/lib/python3.9/site-packages/rest_framework/serializers.py", line 1124, in get_field_names
    assert not (fields is None and exclude is None), (
AssertionError: ("Creating a ModelSerializer without either the 'fields' attribute or the 'exclude' attribute has been deprecated since 3.3.0, and is now disallowed. Add an explicit fields = '__all__' to the IOCSerializer serializer.",)
2022-02-05 08:25:56,774 - django.server - log_message - ERROR - "GET /api/enrichment?query=140.246.171.141 HTTP/1.1" 500 146241
